Workbook

Sheet פירוט מאורות 01.26
A1: מ.ז | B1: מספר ספק כולל | C1: מספר ספק מאורות | D1: שם | E1: תאור | F1: סכום | G1: מסגרת | H1: קבוע / לא קבוע | I1: תאריך סיום | J1: טופס | K1: הערות | L1: קטגוריה | M1: בנק | N1: סניף | O1: חשבון
A2: 326139953 | B2: 202446 | D2: אביגדור בינט | E2: תמיכות | F2: 1000 | G2: מ | H2: קבוע
A3: 201582716 | B3: 200083 | C3: =VLOOKUP(A:A,'אלפון בלבד'!D:E,2,0) -> 200129 | D3: אורלנציק דוד | E3: שער התפלה | F3: 3200 | G3: מ | H3: קבוע
A4: 304892110 | B4: 202346 | D4: אלחנן איזנבלט | E4: תמיכות | F4: 3600 | G4: מ | H4: קבוע | L4: חל
A5: 39277199 | B5: 202303 | D5: אפרים עקשטין | E5: תמיכות | F5: 1000 | G5: מ | H5: קבוע
A6: 208816017 | B6: 202373 | C6: =VLOOKUP(A:A,'אלפון בלבד'!D:E,2,0) -> 202373 | D6: אריה פדר | E6: תמיכות | F6: 1500 | G6: מ | H6: קבוע
A7: 25669284 | B7: 200337 | D7: ברקוביץ יהושע | E7: רבנים | F7: 3500 | G7: מ | H7: קבוע
A8: 32168700 | B8: 200122 | D8: ברקוביץ יצחק | E8: רבנים | F8: 3500 | G8: מ | H8: קבוע
A9: 314794488 | B9: 202024 | D9: גוטמן שלמה | E9: רבנים | F9: 3500 | G9: מ | H9: קבוע
A10: 50698794 | B10: 202396 | C10: =VLOOKUP(A:A,'אלפון בלבד'!D:E,2,0) -> 200319 | D10: גולדשטיין ישראל | E10: תמיכות | F10: 1900 | G10: מ | H10: קבוע
A11: 59218016 | B11: 200215 | C11: =VLOOKUP(A:A,'אלפון בלבד'!D:E,2,0) -> 200012 | D11: גלבשטיין זאב | E11: שער התפלה | F11: 1900 | G11: מ | H11: קבוע
A12: 48529265 | B12: 200098 | D12: הרבי | E12: תמיכות | F12: 3200 | G12: מ | H12: קבוע
A13: 55440127 | B13: 200099 | D13: הרבנית | E13: תמיכות | F13: 3200 | G13: מ | H13: קבוע
A14: 305475071 | B14: 200818 | C14: =VLOOKUP(A:A,'אלפון בלבד'!D:E,2,0) -> 200056 | D14: הרש משה | E14: שער התפלה | F14: 3000 | G14: מ | H14: קבוע
A15: 23692627 | B15: 200207 | D15: ויטריאל דב | E15: רבנים | F15: 1000 | G15: מ | H15: קבוע
A16: 205873839 | B16: 202042 | C16: =VLOOKUP(A:A,'אלפון בלבד'!D:E,2,0) -> 202042 | D16: וייס מנחם מנדל | E16: תמיכות | F16: 1000 | G16: מ | H16: קבוע
A17: 308098375 | B17: 200788 | D17: וייץ משה | E17: רבנים | F17: 3500 | G17: מ | H17: קבוע | L17: אשדוד
A18: 212816946 | B18: 202150 | C18: =VLOOKUP(A:A,'אלפון בלבד'!D:E,2,0) -> 200275 | D18: חיים ייגר | E18: שער התפלה | F18: 3500 | G18: מ | H18: קבוע
A19: 59814558 | B19: 200891 | C19: =VLOOKUP(A:A,'אלפון בלבד'!D:E,2,0) -> 200891 | D19: טויסיג בת שבע | E19: תמיכות | F19: 700 | G19: מ | H19: קבוע
A20: 211725650 | B20: 202272 | D20: יהושוע אולמן | E20: תמיכות | F20: 2000 | G20: מ | H20: קבוע
A21: 305584047 | B21: 201090 | D21: יפה צבי | E21: רבנים | F21: 3500 | G21: מ | H21: קבוע | L21: אשדוד
A22: 311600746 | B22: 201408 | D22: ישראל פרידמן | E22: רבנים | F22: 3500 | G22: מ | H22: קבוע | L22: אשדוד
A23: 38125431 | B23: 200130 | D23: מ. החינוך-קובלסקי אשר | E23: שער התפלה | F23: 3500 | G23: מ | H23: קבוע
A24: 305471310 | B24: 200786 | D24: מושקוביץ דניאל זלמן | E24: רבנים | F24: 3500 | G24: מ | H24: קבוע | L24: אשדוד
A25: 200956696 | B25: 202451 | D25: מנחם אליהו רייזנר | E25: תמיכות | F25: 1000 | G25: מ | H25: קבוע
A26: 300665379 | B26: 202486 | C26: =VLOOKUP(A:A,'אלפון בלבד'!D:E,2,0) -> 200334 | D26: מרדכי אודסר | E26: שער התפלה | F26: 3500 | G26: מ | H26: קבוע
A27: 203209986 | B27: 202032 | D27: נוימן יצחק | E27: תמיכות | F27: 1500 | G27: מ | H27: קבוע
A28: 24248775 | B28: 201143 | C28: =VLOOKUP(A:A,'אלפון בלבד'!D:E,2,0) -> 201143 | D28: סגל אברהם יצחק | E28: רבנים | F28: 3500 | G28: מ | H28: קבוע | L28: אשדוד
A29: 300247319 | B29: 202420 | C29: =VLOOKUP(A:A,'אלפון בלבד'!D:E,2,0) -> 200136 | D29: סירקיס חיה רחל | E29: תמיכות | F29: 3500 | G29: מ | H29: קבוע
A30: 39713581 | B30: 200094 | D30: קובלסקי דב | E30: רבנים | F30: 2000 | G30: מ | H30: קבוע
A31: 322716234 | B31: 201906 | C31: =VLOOKUP(A:A,'אלפון בלבד'!D:E,2,0) -> 201906 | D31: קובלסקי יחזקאל | E31: שער התפלה | F31: 3500 | G31: מ | H31: קבוע
A32: 314779588 | B32: 202011 | C32: =VLOOKUP(A:A,'אלפון בלבד'!D:E,2,0) -> 202011 | D32: קלין מנדי | E32: תמיכות | F32: 1200 | G32: מ | H32: קבוע
A33: 301027686 | B33: 202289 | D33: קמינר חנוך | E33: תמיכות | F33: 3600 | G33: מ | H33: קבוע
A34: 204620793 | B34: 201239 | D34: שמעון סופר | E34: תמיכות | F34: 1800 | G34: מ | H34: קבוע
A35: 35793579 | B35: 202488 | C35: =VLOOKUP(A:A,'אלפון בלבד'!D:E,2,0) -> 200257 | D35: שמשון גרינולד | E35: שער התפלה | F35: 3500 | G35: מ | H35: קבוע
A36: 206582447 | B36: 201866 | C36: =VLOOKUP(A:A,'אלפון בלבד'!D:E,2,0) -> 200128 | D36: שפר שמעון | E36: רבנים | F36: 3500 | G36: מ | H36: קבוע | L36: אשדוד
A37: 59178939 | B37: 200093 | D37: איזנשטיין אהרון זאב | E37: רבנים | F37: 3000 | G37: מ | H37: קבוע
A38: 323945436 | B38: 202225 | D38: ישראל קלין | E38: תמיכות | F38: 2000 | G38: מ | H38: קבוע | L38: מרדכי
A39: 52819844 | B39: 200912 | C39: =VLOOKUP(A:A,'אלפון בלבד'!D:E,2,0) -> 200281 | D39: כהן אהרן | E39: שער התפלה | F39: 1800 | G39: מ-נ | H39: קבוע | L39: הוצאות שכ"ל נדבורנא
A40: 23826563 | B40: 200085 | C40: =VLOOKUP(A:A,'אלפון בלבד'!D:E,2,0) -> 200341 | D40: לנדמן פנחס משה | E40: רבנים | F40: 1800 | G40: מ | H40: קבוע
...

Sheet גיליון1
A1: מ.ז | B1: שם | C1: תאור | D1: 46023 | E1: מסגרת | F1: בנק | G1: סניף | H1: חשבון
A2: 215299033 | B2: נפתלי צבי הלפרין | C2: תמיכות חד פעמי | D2: 10000 | E2: מ | F2: 10 | G2: 856 | H2: 728246‎

Sheet סיכום
C1: תוויות שורה | D1: סכום של 01/2026
C2: מ | D2: 158400
C3: מ-נ | D3: 5800
C4: נ | D4: 28200
C5: ע | D5: 60750
C6: ק | D6: 23000
C7: סכום כולל | D7: 276150

Sheet אלפון בלבד
H1: מספר זהות | I1: שם
A2: מספר תעודת זהות | B2: מספר ספק משני כולל | D2: מס.זהות/תיק מס הכנסה | E2: ספק מאורות | H2: 59218016 | I2: גלבשטיין זאב
A3: 37667557 | B3: 10033 | D3: 302884572 | E3: 200010 | H3: 303141675 | I3: גלבשטין שלמה יעקב
A4: 41936667 | B4: 1004493 | D4: 302884572 | E4: 200011 | H4: 305475071 | I4: הרש משה
B5: 1054978 | D5: 59218016 | E5: 200012 | H5: 208389692 | I5: אייזנבך משה אריה
B6: 1067636 | D6: 303141675 | E6: 200013 | H6: 316422658 | I6: זלצר מאיר
A7: 57949406 | B7: 1077808 | D7: 3693392 | E7: 200014 | H7: 36116333 | I7: הרב פתחיה רוט
A8: 557414927 | B8: 1100 | D8: 3693392 | E8: 200015 | H8: 312513278 | I8: לנדאו חנוך
B9: 1610 | D9: 203343405 | E9: 200016 | H9: 51446981 | I9: ברקוביץ שלמה יעקב
B10: 1659 | D10: 302837133 | E10: 200017 | H10: 201582716 | I10: אורלנציק דוד
A11: 201114683 | B11: 1668 | D11: 308376953 | E11: 200018 | H11: 38125431 | I11: מ. החינוך-קובלסקי אשר
A12: 32912180 | B12: 200002 | D12: 30547801 | E12: 200019 | H12: 15447576 | I12: לייפר ישראל
A13: 46115879 | B13: 200003 | D13: 305656100 | E13: 200020 | H13: 323808386 | I13: גוטוין שלום זאב
A14: 300326931 | B14: 200004 | D14: 305525222 | E14: 200021 | H14: 24138992 | I14: גוטפרינד שמואל
A15: 14316137 | B15: 200005 | D15: 308436534 | E15: 200022 | H15: 302879129 | I15: לנדמן שלמה
A16: 59703165 | B16: 200006 | D16: 204044796 | E16: 200023 | H16: 55394001 | I16: צביון שמשון
A17: 23696081 | B17: 200007 | D17: 200984540 | E17: 200024 | H17: 324959683 | I17: פורמנץ משה
A18: 22806145 | B18: 200008 | D18: 36780005 | E18: 200025 | H18: 22838114 | I18: פריד אברהם מאיר | L18: נשלח טופס
A19: 33214545 | B19: 200009 | D19: 305646986 | E19: 200026 | H19: 54201421 | I19: רוזנטל אהרון | L19: לא נשלח טופס
A20: 28608719 | B20: 200010 | D20: 204093793 | E20: 200027 | H20: 56390115 | I20: לנגנוער יהושע
A21: 27901263 | B21: 200011 | D21: 28658466 | E21: 200028 | H21: 208568253 | I21: וייץ נפתלי
A22: 22932040 | B22: 200012 | D22: 300081213 | E22: 200029 | H22: 40117137 | I22: גרינבום מנחם
A23: 32863219 | B23: 200013 | D23: 311606651 | E23: 200030 | H23: 300748878 | I23: רוזנבוים יוסף דוד
A24: 30567457 | B24: 200014 | D24: 27172808 | E24: 200031 | H24: 313519134 | I24: ערבליך משה
A25: 36052777 | B25: 200015 | D25: 62489745 | E25: 200032 | H25: 345996565 | I25: טובנפעלד יעקב
A26: 24253247 | B26: 200016 | D26: 316420074 | E26: 200033 | H26: 36780005 | I26: רוזנבוים חיים מרדכי
A27: 32428781 | B27: 200017 | D27: 301788931 | E27: 200034 | H27: 35793579 | I27: שמשון גרינולד
A28: 25303504 | B28: 200018 | D28: 21975495 | E28: 200035 | H28: 212816946 | I28: ייגר חיים
A29: 61268314 | B29: 200019 | D29: 30809837 | E29: 200036 | H29: 52819844 | I29: כהן אהרון
A30: 33192998 | B30: 200020 | D30: 315771352 | E30: 200037 | H30: 211338884 | I30: וייץ יהושע
A31: 32397804 | B31: 200021 | D31: 62857495 | E31: 200038 | H31: 316071026 | I31: שרייבר אברהם דב
... A74: 40491482 | B74: 200066 | D74: 203121207 | E74: 200089 | H74: 208803155 | I74: עמאר דניאל משה
A75: 6239024 | B75: 200067 | D75: 200331908 | E75: 200090 | H75: 211418223 | I75: משה אליהו פרנקל
A76: 33345166 | B76: 200068 | D76: 203564935 | E76: 200091 | H76: 200227387 | I76: מנדל לוריא
A77: 40852063 | B77: 200069 | D77: 204673982 | E77: 200092 | H77: 212732119 | I77: רוטשילד מאיר
A78: 40535171 | B78: 200070 | D78: 315599738 | E78: 200095 | H78: 43138692 | I78: גרוסמן רחל
A79: 22702294 | B79: 200071 | D79: 51446981 | E79: 200096 | H79: 305644973 | I79: לודמיר ישראל
A80: 33526591 | B80: 200072 | D80: 31772833 | E80: 200099 | H80: 301085338 | I80: אהרן ביכלר
A81: 40427486 | B81: 200073 | D81: 203409677 | E81: 200100 | H81: 208816017 | I81: פדר אריה
A82: 36116333 | B82: 200074 | D82: 40181216 | E82: 200101 | H82: 25303504 | I82: כהן מרדכי
...
